Workbook
Name billion: About!$A$71
Name Diesel_FE_2024: '[1]Fuel Economy Stds'!$F$54
Name Eno_TM: '[2]1997 Table 1a Modified'!#REF!
Name Eno_TM: '[2]1997 Table 1a Modified'!#REF!
Name Eno_TM: '[2]1997 Table 1a Modified'!#REF!
Name Eno_Tons: '[2]1997 Table 1a Modified'!#REF!
Name Eno_Tons: '[2]1997 Table 1a Modified'!#REF!
Name Eno_Tons: '[2]1997 Table 1a Modified'!#REF!
Name EV_FE_2024: '[1]Fuel Economy Stds'!$F$51
Name Gasoline_FE_2024: '[1]Fuel Economy Stds'!#REF!
Name Hydg_FE_2024: '[1]Fuel Economy Stds'!$F$57
Name LPG_FE_2024: '[1]Fuel Economy Stds'!$F$56
Name NG_FE_2024: '[1]Fuel Economy Stds'!$F$52
Name NTS_YR: [3]About!$B$136
Name PHEV_FE_2024: '[1]Fuel Economy Stds'!$F$55
Name Sum_T2: '[2]1997 Table 1a Modified'!#REF!
Name Sum_T2: '[2]1997 Table 1a Modified'!#REF!
Name Sum_T2: '[2]1997 Table 1a Modified'!#REF!
Name Sum_TTM: '[2]1997 Table 1a Modified'!#REF!
Name Sum_TTM: '[2]1997 Table 1a Modified'!#REF!
Name Sum_TTM: '[2]1997 Table 1a Modified'!#REF!
Name ti_tbl_50: #REF!
Name ti_tbl_50: #REF!
Name ti_tbl_50: #REF!
Name ti_tbl_69: #REF!
Name ti_tbl_69: #REF!
Name ti_tbl_69: #REF!
Name trillion: About!$A$72

Sheet About
A1: SYFAFE Start Year Fleet Avg Fuel Economy | B1: Arkansas | C1: 44944 | F1: State | G1: State
B2: =LOOKUP(B1,F2:G51,G2:G51) -> AR | F2: Alabama | G2: AL
A3: Sources: | B3: See Notes section for which vehicle types use which sources | F3: Alaska | G3: AK
B4: EIA | F4: Arizona | G4: AZ
B5: 2020 | F5: Arkansas | G5: AR
B6: Annual Energy Outlook 2020 | F6: California | G6: CA
B7: https://www.eia.gov/outlooks/aeo/tables_ref.cfm | F7: Colorado | G7: CO
B8: Tables 7, 25, 36, 37, 38, 40, 41, 43, 46, 47, 48, 49 | F8: Connecticut | G8: CT
C9: Passenger Rail Scaling | F9: Delaware | G9: DE
B10: Bureau of Transportation Statistics | C10: American Public Transit Association | F10: Florida | G10: FL
B11: 2018 | C11: 2020 | F11: Georgia | G11: GA
B12: National Transportation Statistics | C12: National Transit Database 2019 | F12: Hawaii | G12: HI
B13: https://www.bts.gov/content/us-passenger-miles | C13: https://www.apta.com/research-technical-resources/transit-statistics/ntd-data-tables/ | F13: Idaho | G13: ID
B14: Table 1-40 | C14: Service_Statistic and Fuel and Energy_Statistic | F14: Illinois | G14: IL
F15: Indiana | G15: IN
B16: U.S. Coast Guard | F16: Iowa | G16: IA
B17: 2013 | F17: Kansas | G17: KS
B18: National Recreational Boating Survey 2012 | F18: Kentucky | G18: KY
B19: http://www.uscgboating.org/library/recreational-boating-servey/2012survey%20report.pdf | F19: Louisiana | G19: LA
B20: Page 63, Table 40 | F20: Maine | G20: ME
F21: Maryland | G21: MD
B22: U.S. Department of Energy | F22: Massachusetts | G22: MA
B23: 2015 | F23: Michigan | G23: MI
B24: Fuel Cells Fact Sheet | F24: Minnesota | G24: MN
B25: https://www.energy.gov/sites/prod/files/2015/11/f27/fcto_fuel_cells_fact_sheet.pdf | F25: Mississippi | G25: MS
F26: Missouri | G26: MO
B27: Others as noted on "Calculations Etc" tab | F27: Montana | G27: MT
F28: Nebraska | G28: NE
A29: Notes | F29: Nevada | G29: NV
A30: This variable gives fleet-wide fuel economy in units of cargo distance per BTU. | F30: New Hampshire | G30: NH
F31: New Jersey | G31: NJ
A32: passenger LDVs, freight LDVs and HDVs | F32: New Mexico | G32: NM
A33: Sources: AEO 37, 41, 43, 36, 49 | F33: New York | G33: NY
A34: Vehicle distance traveled and energy consumption by vehicle technology is available for passenger LDVs, commercial light trucks and HDVs. | F34: North Carolina | G34: NC
A35: We sum vehicle distance traveled by technology, divide by energy consumption of that technology, and multiply by the vehicle loading values used in the | F35: North Dakota | G35: ND
A36: EPS to convert from miles/BTU to thing-miles/BTU. The AEO shows 0 energy consumption by battery electric and plug-in hybrid commercial freight | F36: Ohio | G36: OH
A37: trucks in 2019. Therefore, we use 2020 data for those two technologies. | F37: Oklahoma | G37: OK
F38: Oregon | G38: OR
A39: freight rail | F39: Pennsylvania | G39: PA
A40: Sources: AEO 7 | F40: Rhode Island | G40: RI
...

Sheet AEO 7
B1: highogs.d112619a | C1: 2019 | D1: 2020 | E1: 2021 | F1: 2022 | G1: 2023 | H1: 2024 | I1: 2025 | J1: 2026 | K1: 2027 | L1: 2028 | M1: 2029 | N1: 2030 | O1: 2031 | P1: 2032 | Q1: 2033 | R1: 2034 | S1: 2035 | T1: 2036 | U1: 2037 | V1: 2038 | W1: 2039 | X1: 2040 | Y1: 2041 | Z1: 2042 | AA1: 2043 | AB1: 2044 | AC1: 2045 | AD1: 2046 | AE1: 2047 | AF1: 2048 | AG1: 2049 | AH1: 2050
C3: Report | D3: Annual Energy Outlook 2020
C4: Scenario | D4: highogs | G4: High oil and gas supply
C5: Datekey | D5: d112619a
C6: Release Date | E6: January 2020
A10: TKI000 | B10: 7. Transportation Sector Key Indicators and Delivered Energy Consumption
AI12: 2019-
B13: Key Indicators and Consumption | C13: 2019 | D13: 2020 | E13: 2021 | F13: 2022 | G13: 2023 | H13: 2024 | I13: 2025 | J13: 2026 | K13: 2027 | L13: 2028 | M13: 2029 | N13: 2030 | O13: 2031 | P13: 2032 | Q13: 2033 | R13: 2034 | S13: 2035 | T13: 2036 | U13: 2037 | V13: 2038 | W13: 2039 | X13: 2040 | Y13: 2041 | Z13: 2042 | AA13: 2043 | AB13: 2044 | AC13: 2045 | AD13: 2046 | AE13: 2047 | AF13: 2048 | AG13: 2049 | AH13: 2050 | AI13: 2050
B15: Key Indicators
B16: Travel Indicators
B17: (billion vehicle miles traveled)
A18: TKI000:ba_Light-DutyVeh | B18: Light-Duty Vehicles less than 8,501 pounds | C18: 2917.2534 | D18: 2975.1255 | E18: 3025.3584 | F18: 3062.7468 | G18: 3083.9775 | H18: 3096.5911 | I18: 3105.9812 | J18: 3125.592 | K18: 3146.8806 | L18: 3167.6331 | M18: 3188.2371 | N18: 3209.8457 | O18: 3233.3459 | P18: 3252.6282 | Q18: 3271.1394 | R18: 3285.1404 | S18: 3295.6909 | T18: 3311.9399 | U18: 3327.9958 | V18: 3344.2627 | W18: 3361.5449 | X18: 3379.7544 | Y18: 3396.2571 | Z18: 3413.8406 | AA18: 3432.0298 | AB18: 3451.1577 | AC18: 3472.0923 | AD18: 3496.9058 | AE18: 3524.3184 | AF18: 3555.4368 | AG18: 3588.8325 | AH18: 3624.4036 | AI18: 0.007026
A19: TKI000:ba_CommercialLig | B19: Commercial Light Trucks 1/ | C19: 99.321114 | D19: 100.61537 | E19: 102.27555 | F19: 103.79449 | G19: 104.99791 | H19: 105.84502 | I19: 106.78965 | J19: 107.83586 | K19: 109.08619 | L19: 110.31479 | M19: 111.61692 | N19: 112.77087 | O19: 114.26243 | P19: 115.52301 | Q19: 116.87927 | R19: 118.14617 | S19: 119.40303 | T19: 120.80527 | U19: 122.15245 | V19: 123.49687 | W19: 124.85643 | X19: 126.2754 | Y19: 127.71654 | Z19: 129.18462 | AA19: 130.707 | AB19: 132.37408 | AC19: 134.19019 | AD19: 136.27534 | AE19: 138.1423 | AF19: 140.20346 | AG19: 142.3405 | AH19: 144.47952 | AI19: 0.012163
A20: TKI000:ba_FreightTrucks | B20: Freight Trucks greater than 10,000 pounds | C20: 299.98956 | D20: 302.9967 | E20: 307.86118 | F20: 312.26749 | G20: 316.85519 | H20: 319.63693 | I20: 322.73798 | J20: 325.80005 | K20: 329.40594 | L20: 332.56686 | M20: 335.87531 | N20: 338.36066 | O20: 342.56183 | P20: 345.99631 | Q20: 349.88959 | R20: 353.1503 | S20: 356.89838 | T20: 360.95453 | U20: 364.40631 | V20: 367.98541 | W20: 371.4613 | X20: 375.17526 | Y20: 378.96576 | Z20: 382.97611 | AA20: 386.86951 | AB20: 391.47946 | AC20: 396.5683 | AD20: 402.70737 | AE20: 407.39862 | AF20: 413.09305 | AG20: 419.04983 | AH20: 425.07648 | AI20: 0.011306
B21: (billion passenger miles traveled)
A22: TKI000:buspassmiles | B22: Bus Transportation | C22: 210.1385 | D22: 211.1262 | E22: 212.11616 | F22: 213.08595 | G22: 214.01353 | H22: 214.96095 | I22: 215.98413 | J22: 216.98978 | K22: 217.98006 | L22: 218.98109 | M22: 219.96805 | N22: 220.90674 | O22: 221.80705 | P22: 222.67883 | Q22: 223.45596 | R22: 224.19052 | S22: 224.88495 | T22: 225.5426 | U22: 226.16771 | V22: 226.76289 | W22: 227.33022 | X22: 227.87238 | Y22: 228.39172 | Z22: 228.89146 | AA22: 229.37672 | AB22: 229.85208 | AC22: 230.32323 | AD22: 230.79691 | AE22: 231.28061 | AF22: 231.78067 | AG22: 232.30583 | AH22: 232.85057 | AI22: 0.003316
A23: TKI000:railpassmiles | B23: Passenger Rail | C23: 41.270718 | D23: 41.874931 | E23: 42.455513 | F23: 42.941441 | G23: 43.403492 | H23: 43.866783 | I23: 44.310471 | J23: 44.75193 | K23: 45.177658 | L23: 45.617382 | M23: 46.05724 | N23: 46.402245 | O23: 46.841446 | P23: 47.267838 | Q23: 47.680485 | R23: 48.055225 | S23: 48.435219 | T23: 48.803921 | U23: 49.166313 | V23: 49.530781 | W23: 49.890511 | X23: 50.244217 | Y23: 50.573273 | Z23: 50.897018 | AA23: 51.222713 | AB23: 51.549355 | AC23: 51.873222 | AD23: 52.227497 | AE23: 52.585468 | AF23: 52.972961 | AG23: 53.355492 | AH23: 53.757782 | AI23: 0.008563
B24: (billion seat miles available)
A25: TKI000:ba_Air | B25: Air | C25: 1222.9934 | D25: 1245.385 | E25: 1270.2579 | F25: 1290.4578 | G25: 1307.1332 | H25: 1325.8835 | I25: 1346.3998 | J25: 1366.3947 | K25: 1386.9773 | L25: 1409.3759 | M25: 1434.0159 | N25: 1459.4762 | O25: 1485.5172 | P25: 1512.3081 | Q25: 1538.871 | R25: 1563.6233 | S25: 1587.829 | T25: 1613.7333 | U25: 1640.1089 | V25: 1667.4398 | W25: 1695.8134 | X25: 1724.8636 | Y25: 1752.9756 | Z25: 1781.3413 | AA25: 1810.3131 | AB25: 1840.631 | AC25: 1874.0067 | AD25: 1909.9596 | AE25: 1947.4512 | AF25: 1987.4026 | AG25: 2028.574 | AH25: 2071.0894 | AI25: 0.017138
B26: (billion ton miles traveled)
A27: TKI000:ba_Rail | B27: Rail | C27: 1807.9623 | D27: 1730.8405 | E27: 1660.0334 | F27: 1651.2594 | G27: 1652.7242 | H27: 1638.4692 | I27: 1604.7769 | J27: 1643.9995 | K27: 1652.7871 | L27: 1662.7437 | M27: 1655.604 | N27: 1648.3021 | O27: 1654.8008 | P27: 1663.8508 | Q27: 1673.921 | R27: 1684.4979 | S27: 1686.808 | T27: 1698.2738 | U27: 1704.6904 | V27: 1701.2555 | W27: 1711.9681 | X27: 1715.1283 | Y27: 1722.2583 | Z27: 1735.2404 | AA27: 1747.2886 | AB27: 1760.9611 | AC27: 1777.2797 | AD27: 1802.0692 | AE27: 1818.0815 | AF27: 1839.249 | AG27: 1861.9969 | AH27: 1888.5421 | AI27: 0.001408
A28: TKI000:ba_DomesticShipp | B28: Domestic Shipping | C28: 416.68076 | D28: 409.15491 | E28: 404.52988 | F28: 396.47797 | G28: 388.98981 | H28: 379.45697 | I28: 370.07324 | J28: 361.44611 | K28: 352.76407 | L28: 343.56067 | M28: 333.81879 | N28: 323.79498 | O28: 320.25205 | P28: 316.14533 | Q28: 312.6521 | R28: 308.38547 | S28: 304.23715 | T28: 300.63773 | U28: 296.55325 | V28: 292.41882 | W28: 288.76395 | X28: 284.95685 | Y28: 283.66168 | Z28: 282.64859 | AA28: 281.33289 | AB28: 280.51184 | AC28: 279.8728 | AD28: 280.18787 | AE28: 279.40164 | AF28: 279.35028 | AG28: 279.69217 | AH28: 280.25092 | AI28: -0.012713
B30: Energy Efficiency Indicators
B31: (miles per gallon)
A32: TKI000:ca_AvgCAFEStand | B32: New Light-Duty Vehicle CAFE Standard 2/ | C32: 34.359936 | D32: 35.284824 | E32: 36.831001 | F32: 38.399506 | G32: 40.110416 | H32: 41.695168 | I32: 43.801582 | J32: 43.785816 | K32: 43.851311 | L32: 43.92421 | M32: 44.014652 | N32: 44.196796 | O32: 44.303349 | P32: 44.390171 | Q32: 44.493732 | R32: 44.60854 | S32: 44.698715 | T32: 44.789574 | U32: 44.882374 | V32: 44.963428 | W32: 45.039089 | X32: 45.11404 | Y32: 45.19231 | Z32: 45.25729 | AA32: 45.303879 | AB32: 45.340485 | AC32: 45.390274 | AD32: 45.422104 | AE32: 45.456978 | AF32: 45.47982 | AG32: 45.506924 | AH32: 45.514236 | AI32: 0.00911
A33: TKI000:ca_CarCAFEStand | B33: New Car 2/ | C33: 40.551155 | D33: 42.338371 | E33: 44.294533 | F33: 46.414017 | G33: 48.711933 | H33: 50.082985 | I33: 52.773457 | J33: 52.773731 | K33: 52.786339 | L33: 52.786339 | M33: 52.798622 | N33: 52.841564 | O33: 52.841564 | P33: 52.841564 | Q33: 52.841564 | R33: 52.841564 | S33: 52.841564 | T33: 52.841564 | U33: 52.841564 | V33: 52.841564 | W33: 52.841564 | X33: 52.842728 | Y33: 52.844788 | Z33: 52.844788 | AA33: 52.844788 | AB33: 52.844788 | AC33: 52.84753 | AD33: 52.84753 | AE33: 52.848724 | AF33: 52.848724 | AG33: 52.84988 | AH33: 52.84988 | AI33: 0.008582
A34: TKI000:ca_TwukCAFEStand | B34: New Light Truck 2/ | C34: 30.2997 | D34: 30.889185 | E34: 32.380001 | F34: 33.7799 | G34: 35.309071 | H34: 36.976479 | I34: 38.765255 | J34: 38.772991 | K34: 38.772991 | L34: 38.772991 | M34: 38.772991 | N34: 38.772991 | O34: 38.772991 | P34: 38.772991 | Q34: 38.772991 | R34: 38.772991 | S34: 38.772991 | T34: 38.772991 | U34: 38.772991 | V34: 38.772991 | W34: 38.772991 | X34: 38.772991 | Y34: 38.772991 | Z34: 38.772991 | AA34: 38.772991 | AB34: 38.772991 | AC34: 38.772991 | AD34: 38.772991 | AE34: 38.772991 | AF34: 38.772991 | AG34: 38.772991 | AH34: 38.773014 | AI34: 0.007986
A35: TKI000:ca_NewVehCred | B35: Compliance New Light-Duty Vehicle 3/ | C35: 35.348213 | D35: 36.238525 | E35: 37.596539 | F35: 39.37933 | G35: 40.901978 | H35: 42.360344 | I35: 44.567291 | J35: 44.831284 | K35: 44.934002 | L35: 45.040806 | M35: 45.183762 | N35: 45.495754 | O35: 45.787571 | P35: 46.034676 | Q35: 46.317448 | R35: 46.60257 | S35: 46.849384 | T35: 47.060444 | U35: 47.280041 | V35: 47.481697 | W35: 47.659729 | X35: 47.83065 | Y35: 47.980515 | Z35: 48.108444 | AA35: 48.197189 | AB35: 48.262737 | AC35: 48.3549 | AD35: 48.425739 | AE35: 48.504185 | AF35: 48.562855 | AG35: 48.634819 | AH35: 48.674248 | AI35: 0.010373
A36: TKI000:ca_NewCarCred | B36: New Car 3/ | C36: 42.356316 | D36: 43.482601 | E36: 45.545635 | F36: 47.835651 | G36: 49.962463 | H36: 51.477432 | I36: 54.131187 | J36: 54.288181 | K36: 54.274036 | L36: 54.345482 | M36: 54.476521 | N36: 54.755726 | O36: 55.19865 | P36: 55.546597 | Q36: 55.91061 | R36: 56.268238 | S36: 56.616009 | T36: 56.875309 | U36: 57.153564 | V36: 57.42186 | W36: 57.643833 | X36: 57.841148 | Y36: 57.984364 | Z36: 58.118862 | AA36: 58.223202 | AB36: 58.303883 | AC36: 58.397022 | AD36: 58.51268 | AE36: 58.621887 | AF36: 58.738182 | AG36: 58.859608 | AH36: 58.987617 | AI36: 0.010741
A37: TKI000:ca_NewTwukCred | B37: New Light Truck 3/ | C37: 30.865908 | D37: 31.724129 | E37: 32.910633 | F37: 34.543072 | G37: 35.889904 | H37: 37.32349 | I37: 39.26572 | J37: 39.595291 | K37: 39.653728 | L37: 39.666462 | M37: 39.683132 | N37: 39.748066 | O37: 39.797894 | P37: 39.852974 | Q37: 39.920296 | R37: 39.970135 | S37: 40.005047 | T37: 40.02647 | U37: 40.043442 | V37: 40.056137 | W37: 40.064693 | X37: 40.075218 | Y37: 40.075615 | Z37: 40.069695 | AA37: 40.055481 | AB37: 40.038029 | AC37: 40.029408 | AD37: 40.008018 | AE37: 39.996075 | AF37: 39.972542 | AG37: 39.958122 | AH37: 39.929474 | AI37: 0.00834
A38: TKI000:ca_TestedNewVeh | B38: Tested New Light-Duty Vehicle 4/ | C38: 34.962322 | D38: 35.991081 | E38: 37.288235 | F38: 39.051094 | G38: 40.553646 | H38: 41.976017 | I38: 44.120575 | J38: 44.336227 | K38: 44.414066 | L38: 44.500385 | M38: 44.615799 | N38: 44.876507 | O38: 45.111603 | P38: 45.306648 | Q38: 45.531082 | R38: 45.75457 | S38: 45.942371 | T38: 46.09964 | U38: 46.263412 | V38: 46.41185 | W38: 46.541386 | X38: 46.666012 | Y38: 46.777721 | Z38: 46.871037 | AA38: 46.931049 | AB38: 46.971848 | AC38: 47.034363 | AD38: 47.077263 | AE38: 47.126358 | AF38: 47.158012 | AG38: 47.200371 | AH38: 47.214767 | AI38: 0.009739
A39: TKI000:ca_TestedNewCar | B39: New Car 4/ | C39: 41.715885 | D39: 42.872379 | E39: 44.733494 | F39: 46.957069 | G39: 49.003487 | H39: 50.41568 | I39: 52.908669 | J39: 53.035347 | K39: 53.002815 | L39: 53.031281 | M39: 53.101597 | N39: 53.283951 | O39: 53.59354 | P39: 53.82737 | Q39: 54.068119 | R39: 54.300163 | S39: 54.521736 | T39: 54.675041 | U39: 54.843937 | V39: 55.006741 | W39: 55.136219 | X39: 55.248566 | Y39: 55.326115 | Z39: 55.397579 | AA39: 55.445976 | AB39: 55.477283 | AC39: 55.516716 | AD39: 55.571735 | AE39: 55.621513 | AF39: 55.67548 | AG39: 55.732971 | AH39: 55.794552 | AI39: 0.009425
A40: TKI000:ca_TestedNewTwuk | B40: New Light Truck 4/ | C40: 30.612513 | D40: 31.651661 | E40: 32.830524 | F40: 34.456524 | G40: 35.799854 | H40: 37.22747 | I40: 39.151051 | J40: 39.426971 | K40: 39.465645 | L40: 39.475208 | M40: 39.488102 | N40: 39.541683 | O40: 39.581787 | P40: 39.624954 | Q40: 39.679688 | R40: 39.716709 | S40: 39.740402 | T40: 39.750675 | U40: 39.756599 | V40: 39.759041 | W40: 39.758137 | X40: 39.759655 | Y40: 39.75499 | Z40: 39.745636 | AA40: 39.729229 | AB40: 39.710049 | AC40: 39.698334 | AD40: 39.675388 | AE40: 39.66048 | AF40: 39.635681 | AG40: 39.61845 | AH40: 39.589142 | AI40: 0.00833
A41: TKI000:ca_OnRoadNewVeh | B41: On-Road New Light-Duty Vehicle 5/ | C41: 28.524006 | D41: 29.363092 | E41: 30.420794 | F41: 31.858644 | G41: 33.084072 | H41: 34.244457 | I41: 35.994076 | J41: 36.169979 | K41: 36.233746 | L41: 36.304462 | M41: 36.398952 | N41: 36.612297 | O41: 36.804462 | P41: 36.963898 | Q41: 37.147385 | R41: 37.330143 | S41: 37.483685 | T41: 37.612339 | U41: 37.7463 | V41: 37.867699 | W41: 37.973671 | X41: 38.075638 | Y41: 38.16708 | Z41: 38.243473 | AA41: 38.292618 | AB41: 38.326035 | AC41: 38.377235 | AD41: 38.412346 | AE41: 38.45253 | AF41: 38.478436 | AG41: 38.513092 | AH41: 38.524834 | AI41: 0.009742
A42: TKI000:ca_OnRoadNewCar | B42: New Car 5/ | C42: 34.065807 | D42: 35.010216 | E42: 36.530029 | F42: 38.345837 | G42: 40.016972 | H42: 41.170189 | I42: 43.205997 | J42: 43.309448 | K42: 43.282879 | L42: 43.306126 | M42: 43.363548 | N42: 43.512459 | O42: 43.765274 | P42: 43.956223 | Q42: 44.152824 | R42: 44.342316 | S42: 44.523254 | T42: 44.648445 | U42: 44.786369 | V42: 44.919315 | W42: 45.025051 | X42: 45.116795 | Y42: 45.180122 | Z42: 45.23848 | AA42: 45.278004 | AB42: 45.303566 | AC42: 45.33577 | AD42: 45.380699 | AE42: 45.421349 | AF42: 45.46542 | AG42: 45.512367 | AH42: 45.562653 | AI42: 0.009425
A43: TKI000:ca_OnRoadNewTwuk | B43: New Light Truck 5/ | C43: 24.960157 | D43: 25.807436 | E43: 26.768633 | F43: 28.094404 | G43: 29.189699 | H43: 30.353718 | I43: 31.922125 | J43: 32.147099 | K43: 32.178631 | L43: 32.186428 | M43: 32.196941 | N43: 32.240631 | O43: 32.273327 | P43: 32.308525 | Q43: 32.353153 | R43: 32.383339 | S43: 32.402657 | T43: 32.411034 | U43: 32.415863 | V43: 32.417854 | W43: 32.417118 | X43: 32.418354 | Y43: 32.414551 | Z43: 32.406925 | AA43: 32.393547 | AB43: 32.377907 | AC43: 32.368355 | AD43: 32.349648 | AE43: 32.33749 | AF43: 32.317272 | AG43: 32.303223 | AH43: 32.279324 | AI43: 0.00833
... A47: TKI000:ca_FreightTruck | B47: Freight Truck | C47: 7.119165 | D47: 7.17094 | E47: 7.235986 | F47: 7.3073 | G47: 7.388516 | H47: 7.48128 | I47: 7.586367 | J47: 7.703835 | K47: 7.834221 | L47: 7.967885 | M47: 8.108215 | N47: 8.251791 | O47: 8.396469 | P47: 8.537745 | Q47: 8.669586 | R47: 8.791187 | S47: 8.902438 | T47: 9.004374 | U47: 9.096915 | V47: 9.181 | W47: 9.258368 | X47: 9.327685 | Y47: 9.391495 | Z47: 9.448672 | AA47: 9.500283 | AB47: 9.547491 | AC47: 9.591628 | AD47: 9.634123 | AE47: 9.675597 | AF47: 9.716289 | AG47: 9.756433 | AH47: 9.797481 | AI47: 0.010354
B48: (seat miles per gallon)
A49: TKI000:ca_Aircraft | B49: Aircraft | C49: 69.061409 | D49: 69.384445 | E49: 69.706734 | F49: 70.035477 | G49: 70.376755 | H49: 70.734436 | I49: 71.082642 | J49: 71.464615 | K49: 71.895363 | L49: 72.350365 | M49: 72.824806 | N49: 73.293343 | O49: 73.757736 | P49: 74.234024 | Q49: 74.700493 | R49: 75.177055 | S49: 75.653641 | T49: 76.137352 | U49: 76.621902 | V49: 77.107964 | W49: 77.601532 | X49: 78.09996 | Y49: 78.56591 | Z49: 79.031158 | AA49: 79.489037 | AB49: 79.918777 | AC49: 80.345123 | AD49: 80.761703 | AE49: 81.17762 | AF49: 81.591446 | AG49: 81.990547 | AH49: 82.372414 | AI49: 0.005702
B50: (ton miles/thousand Btu)
...

Sheet AEO 35
E1: 2019 | F1: 2020 | G1: 2021 | H1: 2022 | I1: 2023 | J1: 2024 | K1: 2025 | L1: 2026 | M1: 2027 | N1: 2028 | O1: 2029 | P1: 2030 | Q1: 2031 | R1: 2032 | S1: 2033 | T1: 2034 | U1: 2035 | V1: 2036 | W1: 2037 | X1: 2038 | Y1: 2039 | Z1: 2040 | AA1: 2041 | AB1: 2042 | AC1: 2043 | AD1: 2044 | AE1: 2045 | AF1: 2046 | AG1: 2047 | AH1: 2048 | AI1: 2049 | AJ1: 2050 | AK1: Growth (2019-2050)
A10: Table 35. Transportation Sector Energy Use by Mode and Type
A11: https://www.eia.gov/outlooks/aeo/data/browser/#/?id=45-AEO2020&cases=highogs&sourcekey=0
A12: Tue Mar 09 2021 09:44:26 GMT-0800 (Pacific Standard Time)
A13: Source: U.S. Energy Information Administration
B14: full name | C14: api key | D14: units | E14: 2019 | F14: 2020 | G14: 2021 | H14: 2022 | I14: 2023 | J14: 2024 | K14: 2025 | L14: 2026 | M14: 2027 | N14: 2028 | O14: 2029 | P14: 2030 | Q14: 2031 | R14: 2032 | S14: 2033 | T14: 2034 | U14: 2035 | V14: 2036 | W14: 2037 | X14: 2038 | Y14: 2039 | Z14: 2040 | AA14: 2041 | AB14: 2042 | AC14: 2043 | AD14: 2044 | AE14: 2045 | AF14: 2046 | AG14: 2047 | AH14: 2048 | AI14: 2049 | AJ14: 2050 | AK14: Growth (2019-2050)
A15: Energy Use by Mode | C15: 45-AEO2020.2.
A16: Highway | C16: 45-AEO2020.3.
A17: Light-Duty Vehicles | B17: Transportation Energy Use: Highway: Light-Duty Vehicles: High oil and gas supply | C17: 45-AEO2020.4.highogs-d112619a | D17: trillion Btu | E17: 15312.443 | F17: 15307.141 | G17: 15236.72 | H17: 15068.805 | I17: 14804.814 | J17: 14499.308 | K17: 14167.156 | L17: 13909.197 | M17: 13685.46 | N17: 13482.776 | O17: 13299.865 | P17: 13139.07 | Q17: 13002.688 | R17: 12863.338 | S17: 12735.186 | T17: 12602.711 | U17: 12470.581 | V17: 12372.919 | W17: 12287.335 | X17: 12215.112 | Y17: 12158.751 | Z17: 12118.077 | AA17: 12081.139 | AB17: 12057.521 | AC17: 12045.37 | AD17: 12044.358 | AE17: 12055.047 | AF17: 12085.423 | AG17: 12129.279 | AH17: 12190.25 | AI17: 12262.828 | AJ17: 12346.766 | AK17: -0.007
A18: Automobiles | B18: Transportation Energy Use: Highway: Light-Duty Vehicles: Automobiles: High oil and gas supply | C18: 45-AEO2020.5.highogs-d112619a | D18: trillion Btu | E18: 6604.9644 | F18: 6553.7881 | G18: 6462.5918 | H18: 6325.7974 | I18: 6141.5596 | J18: 5945.4087 | K18: 5745.1323 | L18: 5578.6621 | M18: 5431.4175 | N18: 5297.522 | O18: 5177.7271 | P18: 5078.146 | Q18: 4995.5908 | R18: 4919.3291 | S18: 4856.0435 | T18: 4801.0728 | U18: 4754.9814 | V18: 4730.7998 | W18: 4719.7905 | X18: 4721.6392 | Y18: 4736.0396 | Z18: 4762.6094 | AA18: 4794.8496 | AB18: 4835.4375 | AC18: 4882.0771 | AD18: 4933.0811 | AE18: 4988.8521 | AF18: 5051.8193 | AG18: 5119.1323 | AH18: 5191.9043 | AI18: 5267.8442 | AJ18: 5345.6309 | AK18: -0.007
A19: Light Trucks | B19: Transportation Energy Use: Highway: Light-Duty Vehicles: Light Trucks: High oil and gas supply | C19: 45-AEO2020.6.highogs-d112619a | D19: trillion Btu | E19: 8688.5088 | F19: 8734.5293 | G19: 8755.5664 | H19: 8724.8398 | I19: 8645.6162 | J19: 8536.8242 | K19: 8405.5244 | L19: 8314.5137 | M19: 8238.4434 | N19: 8170.0405 | O19: 8107.2686 | P19: 8046.3413 | Q19: 7992.7515 | R19: 7929.8823 | S19: 7865.1968 | T19: 7787.8506 | U19: 7701.9443 | V19: 7628.5342 | W19: 7553.9902 | X19: 7479.9131 | Y19: 7409.1113 | Z19: 7341.791 | AA19: 7272.52 | AB19: 7208.1963 | AC19: 7149.2725 | AD19: 7097.1104 | AE19: 7051.8662 | AF19: 7019.0952 | AG19: 6995.4448 | AH19: 6983.4336 | AI19: 6979.854 | AJ19: 6985.7817 | AK19: -0.007
A20: Motorcycles | B20: Transportation Energy Use: Highway: Light-Duty Vehicles: Motorcycles: High oil and gas supply | C20: 45-AEO2020.7.highogs-d112619a | D20: trillion Btu | E20: 18.970795 | F20: 18.823608 | G20: 18.561443 | H20: 18.168322 | I20: 17.63892 | J20: 17.075298 | K20: 16.499819 | L20: 16.021494 | M20: 15.598401 | N20: 15.213686 | O20: 14.869466 | P20: 14.583327 | Q20: 14.346129 | R20: 14.126972 | S20: 13.94516 | T20: 13.787245 | U20: 13.654823 | V20: 13.585337 | W20: 13.553765 | X20: 13.55909 | Y20: 13.600537 | Z20: 13.677015 | AA20: 13.769792 | AB20: 13.886584 | AC20: 14.020749 | AD20: 14.167451 | AE20: 14.327848 | AF20: 14.508926 | AG20: 14.702455 | AH20: 14.911672 | AI20: 15.129991 | AJ20: 15.353589 | AK20: -0.007
A21: Commercial Light Trucks | B21: Transportation Energy Use: Highway: Commercial Light Trucks: High oil and gas supply | C21: 45-AEO2020.8.highogs-d112619a | D21: trillion Btu | E21: 891.02838 | F21: 891.90326 | G21: 895.8894 | H21: 897.86987 | I21: 897.09033 | J21: 893.17987 | K21: 892.63629 | L21: 892.01526 | M21: 892.60571 | N21: 893.64764 | O21: 895.48633 | P21: 896.71252 | Q21: 901.31744 | R21: 904.84607 | S21: 909.85718 | T21: 914.96765 | U21: 920.24628 | V21: 927.07892 | W21: 934.28284 | X21: 941.58032 | Y21: 949.26141 | Z21: 957.78931 | AA21: 966.8446 | AB21: 975.90601 | AC21: 986.1098 | AD21: 997.79096 | AE21: 1010.6874 | AF21: 1027.0737 | AG21: 1040.2635 | AH21: 1054.5718 | AI21: 1069.2462 | AJ21: 1083.7993 | AK21: 0.006
A22: Buses | B22: Transportation Energy Use: Highway: Buses: High oil and gas supply | C22: 45-AEO2020.9.highogs-d112619a | D22: trillion Btu | E22: 238.53146 | F22: 239.89018 | G22: 241.25854 | H22: 242.60852 | I22: 243.91312 | J22: 245.2515 | K22: 246.68358 | L22: 248.10384 | M22: 249.51576 | N22: 250.95306 | O22: 252.38295 | P22: 253.71747 | Q22: 255.00951 | R22: 256.26871 | S22: 257.40616 | T22: 258.48618 | U22: 259.50766 | V22: 260.47018 | W22: 261.37662 | X22: 262.22324 | Y22: 263.00284 | Z22: 263.71384 | AA22: 264.35327 | AB22: 264.92453 | AC22: 265.43933 | AD22: 265.90439 | AE22: 266.33295 | AF22: 266.74771 | AG22: 267.1767 | AH22: 267.64749 | AI22: 268.20847 | AJ22: 268.87695 | AK22: 0.004
A23: Transit | B23: Transportation Energy Use: Highway: Buses: Transit: High oil and gas supply | C23: 45-AEO2020.10.highogs-d112619a | D23: trillion Btu | E23: 99.315071 | F23: 99.945122 | G23: 100.56989 | H23: 101.19645 | I23: 101.8311 | J23: 102.44681 | K23: 103.00167 | L23: 103.5542 | M23: 104.09944 | N23: 104.62385 | O23: 105.14225 | P23: 105.59572 | Q23: 106.02787 | R23: 106.43801 | S23: 106.85069 | T23: 107.24017 | U23: 107.60039 | V23: 107.92464 | W23: 108.20892 | X23: 108.4436 | Y23: 108.61575 | Z23: 108.71909 | AA23: 108.74683 | AB23: 108.69933 | AC23: 108.58459 | AD23: 108.40518 | AE23: 108.17055 | AF23: 107.90131 | AG23: 107.62363 | AH23: 107.36424 | AI23: 107.17227 | AJ23: 107.07778 | AK23: 0.002
A24: Intercity | B24: Transportation Energy Use: Highway: Buses: Intercity: High oil and gas supply | C24: 45-AEO2020.11.highogs-d112619a | D24: trillion Btu | E24: 34.017525 | F24: 34.295715 | G24: 34.571033 | H24: 34.845947 | I24: 35.122425 | J24: 35.390961 | K24: 35.642731 | L24: 35.891884 | M24: 36.136688 | N24: 36.372597 | O24: 36.604843 | P24: 36.834064 | Q24: 37.057114 | R24: 37.274578 | S24: 37.495804 | T24: 37.713417 | U24: 37.927135 | V24: 38.136677 | W24: 38.341736 | X24: 38.542122 | Y24: 38.737698 | Z24: 38.928463 | AA24: 39.114555 | AB24: 39.296169 | AC24: 39.473579 | AD24: 39.647072 | AE24: 39.817013 | AF24: 39.983807 | AG24: 40.147793 | AH24: 40.309471 | AI24: 40.469448 | AJ24: 40.627487 | AK24: 0.006
A25: School | B25: Transportation Energy Use: Highway: Buses: School: High oil and gas supply | C25: 45-AEO2020.12.highogs-d112619a | D25: trillion Btu | E25: 105.19891 | F25: 105.64934 | G25: 106.1176 | H25: 106.56614 | I25: 106.9596 | J25: 107.41371 | K25: 108.03915 | L25: 108.65778 | M25: 109.27963 | N25: 109.95661 | O25: 110.63587 | P25: 111.28769 | Q25: 111.9245 | R25: 112.55617 | S25: 113.05969 | T25: 113.53259 | U25: 113.98013 | V25: 114.40887 | W25: 114.82594 | X25: 115.2375 | Y25: 115.64941 | Z25: 116.06626 | AA25: 116.49187 | AB25: 116.92904 | AC25: 117.38118 | AD25: 117.85213 | AE25: 118.34538 | AF25: 118.86262 | AG25: 119.40527 | AH25: 119.97376 | AI25: 120.56672 | AJ25: 121.17171 | AK25: 0.005
A26: Freight Trucks | B26: Transportation Energy Use: Highway: Freight Trucks: High oil and gas supply | C26: 45-AEO2020.13.highogs-d112619a | D26: trillion Btu | E26: 5881.6938 | F26: 5905.2188 | G26: 5953.2412 | H26: 5985.7578 | I26: 6012.811 | J26: 5996.0127 | K26: 5975.9307 | L26: 5946.1875 | M26: 5917.5103 | N26: 5879.7197 | O26: 5841.2886 | P26: 5788.1685 | Q26: 5765.2397 | R26: 5732.8828 | S26: 5715.4565 | T26: 5694.999 | U26: 5689.6113 | V26: 5695.0806 | W26: 5696.8452 | X26: 5705.6021 | Y26: 5717.1274 | Z26: 5737.4014 | AA26: 5762.4326 | AB26: 5795.2007 | AC26: 5829.8892 | AD26: 5878.4766 | AE26: 5936.4565 | AF26: 6011.3896 | AG26: 6065.6465 | AH26: 6135.8477 | AI26: 6210.5356 | AJ26: 6286.1934 | AK26: 0.002
A27: Light Medium | B27: Transportation Energy Use: Highway: Freight Trucks: Light Medium: High oil and gas supply | C27: 45-AEO2020.14.highogs-d112619a | D27: trillion Btu | E27: 653.09912 | F27: 654.05658 | G27: 664.6781 | H27: 669.36182 | I27: 674.8158 | J27: 677.23505 | K27: 680.64838 | L27: 683.49329 | M27: 687.08698 | N27: 690.2002 | O27: 693.99316 | P27: 697.10449 | Q27: 704.64301 | R27: 711.11914 | S27: 719.18726 | T27: 726.89185 | U27: 736.56897 | V27: 746.99585 | W27: 755.67902 | X27: 764.26233 | Y27: 772.81659 | Z27: 781.92377 | AA27: 791.5379 | AB27: 801.55286 | AC27: 811.25696 | AD27: 822.5852 | AE27: 834.92804 | AF27: 849.58417 | AG27: 861.80377 | AH27: 876.91168 | AI27: 892.96716 | AJ27: 910.64691 | AK27: 0.011
A28: Medium | B28: Transportation Energy Use: Highway: Freight Trucks: Medium: High oil and gas supply | C28: 45-AEO2020.15.highogs-d112619a | D28: trillion Btu | E28: 910.4176 | F28: 904.67218 | G28: 906.67468 | H28: 910.82416 | I28: 916.18927 | J28: 916.7547 | K28: 917.79553 | L28: 919.64648 | M28: 923.70306 | N28: 928.14789 | O28: 932.71014 | P28: 934.43811 | Q28: 940.39081 | R28: 945.41644 | S28: 952.71179 | T28: 959.54273 | U28: 969.2384 | V28: 981.72199 | W28: 993.88721 | X28: 1007.3842 | Y28: 1021.9026 | Z28: 1038.1415 | AA28: 1055.7887 | AB28: 1075.1769 | AC28: 1096.2792 | AD28: 1121.1508 | AE28: 1148.5773 | AF28: 1180.0684 | AG28: 1208.2478 | AH28: 1240.3015 | AI28: 1274.1514 | AJ28: 1308.8241 | AK28: 0.012
A29: Large (> 26000 pounds) | B29: Transportation Energy Use: Highway: Freight Trucks: Large: High oil and gas supply | C29: 45-AEO2020.16.highogs-d112619a | D29: trillion Btu | E29: 4318.1768 | F29: 4346.4902 | G29: 4381.8887 | H29: 4405.5718 | I29: 4421.8057 | J29: 4402.0229 | K29: 4377.4868 | L29: 4343.0479 | M29: 4306.7202 | N29: 4261.3721 | O29: 4214.5854 | P29: 4156.6255 | Q29: 4120.2056 | R29: 4076.3474 | S29: 4043.5571 | T29: 4008.5645 | U29: 3983.8047 | V29: 3966.3625 | W29: 3947.2788 | X29: 3933.9556 | Y29: 3922.4082 | Z29: 3917.3357 | AA29: 3915.1064 | AB29: 3918.4707 | AC29: 3922.3528 | AD29: 3934.7407 | AE29: 3952.9514 | AF29: 3981.7366 | AG29: 3995.5945 | AH29: 4018.6345 | AI29: 4043.4175 | AJ29: 4066.7219 | AK29: -0.002
A30: Non-Highway | C30: 45-AEO2020.18.
A31: Air | B31: Transportation Energy Use: Non-Highway: Air: High oil and gas supply | C31: 45-AEO2020.19.highogs-d112619a | D31: trillion Btu | E31: 2640.9438 | F31: 2673.0667 | G31: 2706.3496 | H31: 2732.1909 | I31: 2752.4333 | J31: 2776.094 | K31: 2803.1313 | L31: 2828.6794 | M31: 2853.5171 | N31: 2879.8105 | O31: 2908.5222 | P31: 2937.1985 | Q31: 2967.3972 | R31: 2997.719 | S31: 3027.5989 | T31: 3053.2073 | U31: 3077.6519 | V31: 3104.4258 | W31: 3132.1252 | X31: 3160.3247 | Y31: 3189.8337 | Z31: 3220.1482 | AA31: 3250.1726 | AB31: 3279.9529 | AC31: 3310.7305 | AD31: 3344.5698 | AE31: 3383.1245 | AF31: 3426.0435 | AG31: 3471.1809 | AH31: 3520.3723 | AI31: 3571.7424 | AJ31: 3624.8132 | AK31: 0.01
A32: General Aviation | B32: Transportation Energy Use: Non-Highway: Air: General Aviation: High oil and gas supply | C32: 45-AEO2020.20.highogs-d112619a | D32: trillion Btu | E32: 147.15953 | F32: 148.67065 | G32: 150.24031 | H32: 151.45824 | I32: 152.41161 | J32: 153.52972 | K32: 154.81004 | L32: 156.02063 | M32: 157.19858 | N32: 158.44652 | O32: 159.81043 | P32: 161.17323 | Q32: 162.60881 | R32: 164.05092 | S32: 165.47211 | T32: 166.69023 | U32: 167.85316 | V32: 169.12738 | W32: 170.44545 | X32: 171.78783 | Y32: 173.19257 | Z32: 174.6355 | AA32: 176.06506 | AB32: 177.48273 | AC32: 178.94806 | AD32: 180.55942 | AE32: 182.39519 | AF32: 184.43875 | AG32: 186.58804 | AH32: 188.93048 | AI32: 191.37645 | AJ32: 193.90372 | AK32: 0.009
A33: Domestic Air Carriers | B33: Transportation Energy Use: Non-Highway: Air: Domestic Air Carriers: High oil and gas supply | C33: 45-AEO2020.21.highogs-d112619a | D33: trillion Btu | E33: 1635.2072 | F33: 1650.1774 | G33: 1668.0919 | H33: 1679.7188 | I33: 1686.4562 | J33: 1695.1627 | K33: 1706.0006 | L33: 1715.1434 | M33: 1723.5776 | N33: 1733.3123 | O33: 1744.8951 | P33: 1757.2142 | Q33: 1769.8943 | R33: 1782.7548 | S33: 1795.1801 | T33: 1804.9639 | U33: 1813.7872 | V33: 1823.9509 | W33: 1834.2209 | X33: 1845.1093 | Y33: 1856.511 | Z33: 1868.0806 | AA33: 1878.879 | AB33: 1889.5753 | AC33: 1900.677 | AD33: 1913.4052 | AE33: 1928.8691 | AF33: 1946.6647 | AG33: 1965.5006 | AH33: 1986.2723 | AI33: 2008.037 | AJ33: 2031.1687 | AK33: 0.007
A34: International Air Carriers | B34: Transportation Energy Use: Non-Highway: Air: International Air Carriers: High oil and gas supply | C34: 45-AEO2020.22.highogs-d112619a | D34: trillion Btu | E34: 714.12396 | F34: 730.10999 | G34: 747.56818 | H34: 762.11304 | I34: 774.37378 | J34: 787.69373 | K34: 802.18713 | L34: 815.99738 | M34: 829.63293 | N34: 844.11841 | O34: 859.7572 | P34: 875.99011 | Q34: 892.64008 | R34: 909.63281 | S34: 926.63452 | T34: 942.45721 | U34: 957.98291 | V34: 974.48108 | W34: 991.28644 | X34: 1008.6912 | Y34: 1026.6801 | Z34: 1045.0632 | AA34: 1063.4751 | AB34: 1082.0919 | AC34: 1101.2108 | AD34: 1121.5653 | AE34: 1143.8585 | AF34: 1167.8917 | AG34: 1192.9176 | AH34: 1219.5104 | AI34: 1247.116 | AJ34: 1275.6644 | AK34: 0.019
A35: Freight Carriers | B35: Transportation Energy Use: Non-Highway: Air: Freight Carriers: High oil and gas supply | C35: 45-AEO2020.23.highogs-d112619a | D35: trillion Btu | E35: 144.45309 | F35: 144.10854 | G35: 140.44926 | H35: 138.90096 | I35: 139.19157 | J35: 139.70784 | K35: 140.13348 | L35: 141.51813 | M35: 143.10794 | N35: 143.93337 | O35: 144.05933 | P35: 142.82098 | Q35: 142.25418 | R35: 141.28052 | S35: 140.31224 | T35: 139.09587 | U35: 138.02847 | V35: 136.8662 | W35: 136.17244 | X35: 134.73627 | Y35: 133.44994 | Z35: 132.36883 | AA35: 131.75345 | AB35: 130.80298 | AC35: 129.89465 | AD35: 129.03992 | AE35: 128.00151 | AF35: 127.04829 | AG35: 126.17458 | AH35: 125.65891 | AI35: 125.21304 | AJ35: 124.07639 | AK35: -0.005
A36: Water | B36: Transportation Energy Use: Non-Highway: Water: High oil and gas supply | C36: 45-AEO2020.24.highogs-d112619a | D36: trillion Btu | E36: 1262.223 | F36: 1343.0319 | G36: 1303.8322 | H36: 1217.3433 | I36: 1220.3928 | J36: 1202.0239 | K36: 1213.1461 | L36: 1186.0875 | M36: 1195.2208 | N36: 1194.0463 | O36: 1177.7366 | P36: 1189.1602 | Q36: 1188.8616 | R36: 1176.0665 | S36: 1184.9402 | T36: 1183.4945 | U36: 1178.7653 | V36: 1167.1626 | W36: 1172.2524 | X36: 1160.2507 | Y36: 1158.2136 | Z36: 1162.8938 | AA36: 1150.8705 | AB36: 1148.344 | AC36: 1144.6913 | AD36: 1140.4397 | AE36: 1137.3685 | AF36: 1135.8217 | AG36: 1132.6587 | AH36: 1130.8229 | AI36: 1129.4923 | AJ36: 1128.8481 | AK36: -0.004
A37: Freight | B37: Transportation Energy Use: Non-Highway: Water: Freight: High oil and gas supply | C37: 45-AEO2020.25.highogs-d112619a | D37: trillion Btu | E37: 1016.7357 | F37: 1096.7845 | G37: 1056.941 | H37: 970.11517 | I37: 972.99194 | J37: 954.46289 | K37: 965.3996 | L37: 938.21533 | M37: 947.27319 | N37: 946.01202 | O37: 929.61755 | P37: 941.0318 | Q37: 940.74268 | R37: 927.98798 | S37: 936.99731 | T37: 935.79016 | U37: 931.38336 | V37: 920.11212 | W37: 925.58014 | X37: 913.98023 | Y37: 912.36902 | Z37: 917.52997 | AA37: 906.03326 | AB37: 904.10101 | AC37: 901.05493 | AD37: 897.40314 | AE37: 894.90204 | AF37: 893.89569 | AG37: 891.2721 | AH37: 889.96435 | AI37: 889.17596 | AJ37: 889.08813 | AK37: -0.004
A38: Domestic Shipping | B38: Transportation Energy Use: Non-Highway: Water: Freight: Domestic Shipping: High oil and gas supply | C38: 45-AEO2020.26.highogs-d112619a | D38: trillion Btu | E38: 89.408684 | F38: 87.946663 | G38: 85.825142 | H38: 83.143684 | I38: 81.043098 | J38: 78.540054 | K38: 76.102608 | L38: 73.8507 | M38: 71.605797 | N38: 69.277527 | O38: 66.86528 | P38: 64.420662 | Q38: 63.281223 | R38: 62.043758 | S38: 60.933224 | T38: 59.681496 | U38: 58.471172 | V38: 57.385189 | W38: 56.208904 | X38: 55.024643 | Y38: 53.932945 | Z38: 52.831013 | AA38: 52.282791 | AB38: 51.791668 | AC38: 51.248352 | AD38: 50.799305 | AE38: 50.387039 | AF38: 50.149246 | AG38: 49.715466 | AH38: 49.415421 | AI38: 49.187336 | AJ38: 48.997417 | AK38: -0.019
A39: International Shipping | B39: Transportation Energy Use: Non-Highway: Water: Freight: International Shipping: High oil and gas supply | C39: 45-AEO2020.27.highogs-d112619a | D39: trillion Btu | E39: 927.32696 | F39: 1008.8378 | G39: 971.11591 | H39: 886.9715 | I39: 891.94885 | J39: 875.92285 | K39: 889.297 | L39: 864.36462 | M39: 875.66742 | N39: 876.7345 | O39: 862.75226 | P39: 876.61114 | Q39: 877.46143 | R39: 865.94421 | S39: 876.06409 | T39: 876.10864 | U39: 872.91217 | V39: 862.72693 | W39: 869.37122 | X39: 858.95557 | Y39: 858.4361 | Z39: 864.69898 | AA39: 853.75049 | AB39: 852.30933 | AC39: 849.80658 | AD39: 846.60382 | AE39: 844.51501 | AF39: 843.74646 | AG39: 841.55664 | AH39: 840.54895 | AI39: 839.98865 | AJ39: 840.0907 | AK39: -0.003
A40: Recreational Boats | B40: Transportation Energy Use: Non-Highway: Water: Recreational Boats: High oil and gas supply | C40: 45-AEO2020.28.highogs-d112619a | D40: trillion Btu | E40: 245.48737 | F40: 246.24731 | G40: 246.89113 | H40: 247.22803 | I40: 247.40088 | J40: 247.561 | K40: 247.74658 | L40: 247.87222 | M40: 247.94768 | N40: 248.03426 | O40: 248.11905 | P40: 248.12834 | Q40: 248.11883 | R40: 248.07858 | S40: 247.94284 | T40: 247.70436 | U40: 247.38197 | V40: 247.05051 | W40: 246.67229 | X40: 246.27057 | Y40: 245.84454 | Z40: 245.36371 | AA40: 244.83713 | AB40: 244.24297 | AC40: 243.63638 | AD40: 243.03659 | AE40: 242.46649 | AF40: 241.926 | AG40: 241.38654 | AH40: 240.85849 | AI40: 240.31628 | AJ40: 239.76006 | AK40: -0.001
A41: Rail | B41: Transportation Energy Use: Non-Highway: Rail: High oil and gas supply | C41: 45-AEO2020.29.highogs-d112619a | D41: trillion Btu | E41: 570.61951 | F41: 546.03455 | G41: 523.50366 | H41: 518.65912 | I41: 516.72046 | J41: 510.4024 | K41: 498.73596 | L41: 507.30695 | M41: 507.39301 | N41: 507.81271 | O41: 503.59045 | P41: 499.21533 | Q41: 498.74268 | R41: 498.92212 | S41: 499.33661 | T41: 499.81677 | U41: 498.15179 | V41: 498.84726 | W41: 498.22153 | X41: 495.09177 | Y41: 495.578 | Z41: 494.14456 | AA41: 493.68311 | AB41: 494.67279 | AC41: 495.42117 | AD41: 496.5531 | AE41: 498.297 | AF41: 502.10562 | AG41: 503.72974 | AH41: 506.58588 | AI41: 509.73932 | AJ41: 513.75122 | AK41: -0.003
A42: Freight | B42: Transportation Energy Use: Non-Highway: Rail: Freight: High oil and gas supply | C42: 45-AEO2020.30.highogs-d112619a | D42: trillion Btu | E42: 521.49481 | F42: 496.0322 | G42: 472.67419 | H42: 467.14597 | I42: 464.54727 | J42: 457.57266 | K42: 445.27527 | L42: 453.21878 | M42: 452.70502 | N42: 452.49731 | O42: 447.65079 | P42: 442.80438 | Q42: 441.68543 | R42: 441.23898 | S42: 441.04895 | T42: 440.97555 | U42: 438.7345 | V42: 438.8703 | W42: 437.68955 | X42: 433.99274 | Y42: 433.91113 | Z42: 431.91071 | AA42: 430.91129 | AB42: 431.36157 | AC42: 431.55756 | AD42: 432.13159 | AE42: 433.32553 | AF42: 436.53812 | AG42: 437.57886 | AH42: 439.82074 | AI42: 442.39105 | AJ42: 445.80643 | AK42: -0.005
... A53: Total | B53: Transportation Energy Use: Total: High oil and gas supply | C53: 45-AEO2020.43.highogs-d112619a | D53: trillion Btu | E53: 28113.373 | F53: 28230.869 | G53: 28208.764 | H53: 28011.26 | I53: 27787.75 | J53: 27465.568 | K53: 27155.045 | L53: 26881.73 | M53: 26659.488 | N53: 26449.74 | O53: 26245.27 | P53: 26070.695 | Q53: 25953.711 | R53: 25807.697 | S53: 25707.465 | T53: 25586.844 | U53: 25476.686 | V53: 25419.227 | W53: 25381.16 | X53: 25347.111 | Y53: 25350.15 | Z53: 25380.1 | AA53: 25402.027 | AB53: 25464.266 | AC53: 25534.621 | AD53: 25633.875 | AE53: 25761.697 | AF53: 25939.467 | AG53: 26103.859 | AH53: 26310.646 | AI53: 26534.156 | AJ53: 26773.309 | AK53: -0.002
A54: Energy Use by Type | C54: 45-AEO2020.45.
A55: Motor Gasoline excluding E85 | B55: Transportation Energy Use: Petroleum: Motor Gasoline: High oil and gas supply | C55: 45-AEO2020.46.highogs-d112619a | D55: trillion Btu | E55: 16549.932 | F55: 16522.381 | G55: 16441.443 | H55: 16259.478 | I55: 15982.112 | J55: 15662.639 | K55: 15317.657 | L55: 15050.626 | M55: 14823.722 | N55: 14617.606 | O55: 14432.009 | P55: 14261.387 | Q55: 14125.966 | R55: 13985.438 | S55: 13858.184 | T55: 13726.722 | U55: 13596.663 | V55: 13502.562 | W55: 13420.314 | X55: 13351.398 | Y55: 13301.795 | Z55: 13268.043 | AA55: 13238.325 | AB55: 13224.984 | AC55: 13219.75 | AD55: 13229.154 | AE55: 13257.222 | AF55: 13305.808 | AG55: 13364.965 | AH55: 13441.875 | AI55: 13531.795 | AJ55: 13633.456 | AK55: -0.006
A56: E85 | B56: Transportation Energy Use: E85: High oil and gas supply | C56: 45-AEO2020.47.highogs-d112619a | D56: trillion Btu | E56: 19.862495 | F56: 25.243965 | G56: 25.534731 | H56: 26.681034 | I56: 28.335787 | J56: 29.3298 | K56: 33.204823 | L56: 34.160919 | M56: 32.102829 | N56: 31.337315 | O56: 31.143978 | P56: 35.832336 | Q56: 34.118191 | R56: 33.44109 | S56: 33.061779 | T56: 32.209557 | U56: 32.014435 | V56: 32.282661 | W56: 32.174183 | X56: 32.11113 | Y56: 29.198238 | Z56: 26.767563 | AA56: 25.802158 | AB56: 22.979017 | AC56: 23.296274 | AD56: 23.40741 | AE56: 19.103216 | AF56: 17.506731 | AG56: 14.981414 | AH56: 14.800054 | AI56: 14.678515 | AJ56: 15.4762 | AK56: -0.008
A57: Diesel | B57: Transportation Energy Use: Petroleum: Diesel: High oil and gas supply | C57: 45-AEO2020.48.highogs-d112619a | D57: trillion Btu | E57: 6996.2236 | F57: 7122.9868 | G57: 7057.7153 | H57: 6959.8804 | I57: 6971.4199 | J57: 6968.647 | K57: 6908.6284 | L57: 6926.4014 | M57: 6869.417 | N57: 6819.3154 | O57: 6785.3198 | P57: 6695.3833 | Q57: 6654.563 | R57: 6623.9097 | S57: 6571.1802 | T57: 6531.3228 | U57: 6509.1025 | V57: 6508.6719 | W57: 6476.4233 | X57: 6475.1284 | Y57: 6463.6514 | Z57: 6448.1069 | AA57: 6461.8262 | AB57: 6467.6245 | AC57: 6478.2539 | AD57: 6502.7236 | AE57: 6534.0654 | AF57: 6580.793 | AG57: 6608.4395 | AH57: 6648.3291 | AI57: 6689.8101 | AJ57: 6730.1035 | AK57: -0.001
A58: Jet Fuel (kerosene & naphtha) | B58: Transportation Energy Use: Petroleum: Jet Fuel: High oil and gas supply | C58: 45-AEO2020.49.highogs-d112619a | D58: trillion Btu | E58: 3001.7886 | F58: 3036.5679 | G58: 3067.1274 | H58: 3089.0298 | I58: 3097.9346 | J58: 3114.0493 | K58: 3139.6846 | L58: 3163.8328 | M58: 3188.2424 | N58: 3216.4604 | O58: 3244.3743 | P58: 3272.5186 | Q58: 3302.7859 | R58: 3333.1934 | S58: 3363.177 | T58: 3388.9058 | U58: 3413.4873 | V58: 3440.4167 | W58: 3468.2896 | X58: 3496.677 | Y58: 3526.3887 | Z58: 3556.9182 | AA58: 3587.1692 | AB58: 3617.1851 | AC58: 3648.2073 | AD58: 3682.2991 | AE58: 3721.113 | AF58: 3764.2976 | AG58: 3809.7058 | AH58: 3859.1726 | AI58: 3910.8228 | AJ58: 3964.177 | AK58: 0.009
...

Sheet AEO 36
F1: 2019 | G1: 2020 | H1: 2021 | I1: 2022 | J1: 2023 | K1: 2024 | L1: 2025 | M1: 2026 | N1: 2027 | O1: 2028 | P1: 2029 | Q1: 2030 | R1: 2031 | S1: 2032 | T1: 2033 | U1: 2034 | V1: 2035 | W1: 2036 | X1: 2037 | Y1: 2038 | Z1: 2039 | AA1: 2040 | AB1: 2041 | AC1: 2042 | AD1: 2043 | AE1: 2044 | AF1: 2045 | AG1: 2046 | AH1: 2047 | AI1: 2048 | AJ1: 2049 | AK1: 2050 | AL1: Growth (2019-2050)
B10: Table 36. Transportation Sector Energy Use by Fuel Type Within a Mode
B11: https://www.eia.gov/outlooks/aeo/data/browser/#/?id=46-AEO2020&cases=highogs&sourcekey=0
B12: Tue Mar 09 2021 09:59:28 GMT-0800 (Pacific Standard Time)
B13: Source: U.S. Energy Information Administration
C14: full name | D14: api key | E14: units | F14: 2019 | G14: 2020 | H14: 2021 | I14: 2022 | J14: 2023 | K14: 2024 | L14: 2025 | M14: 2026 | N14: 2027 | O14: 2028 | P14: 2029 | Q14: 2030 | R14: 2031 | S14: 2032 | T14: 2033 | U14: 2034 | V14: 2035 | W14: 2036 | X14: 2037 | Y14: 2038 | Z14: 2039 | AA14: 2040 | AB14: 2041 | AC14: 2042 | AD14: 2043 | AE14: 2044 | AF14: 2045 | AG14: 2046 | AH14: 2047 | AI14: 2048 | AJ14: 2049 | AK14: 2050 | AL14: Growth (2019-2050)
B15: Light-Duty Vehicle | C15: Transportation Energy Use: Light-Duty Vehicle: Total: High oil and gas supply | D15: 46-AEO2020.2.highogs-d112619a | E15: trillion Btu | F15: 15312.444 | G15: 15307.14 | H15: 15236.718 | I15: 15068.805 | J15: 14804.812 | K15: 14499.306 | L15: 14167.156 | M15: 13909.195 | N15: 13685.458 | O15: 13482.775 | P15: 13299.862 | Q15: 13139.068 | R15: 13002.686 | S15: 12863.336 | T15: 12735.183 | U15: 12602.708 | V15: 12470.578 | W15: 12372.916 | X15: 12287.332 | Y15: 12215.108 | Z15: 12158.749 | AA15: 12118.073 | AB15: 12081.136 | AC15: 12057.517 | AD15: 12045.366 | AE15: 12044.355 | AF15: 12055.041 | AG15: 12085.418 | AH15: 12129.274 | AI15: 12190.245 | AJ15: 12262.822 | AK15: 12346.761 | AL15: -0.007
B16: Motor Gasoline excluding E85 | C16: Transportation Energy Use: Light-Duty Vehicle: Motor Gasoline: High oil and gas supply | D16: 46-AEO2020.3.highogs-d112619a | E16: trillion Btu | F16: 15199.481 | G16: 15180.85 | H16: 15098.542 | I16: 14917.298 | J16: 14640.975 | K16: 14325.252 | L16: 13980.959 | M16: 13712.799 | N16: 13481.304 | O16: 13269.926 | P16: 13077.647 | Q16: 12903.024 | R16: 12756.388 | S16: 12605.884 | T16: 12465.86 | U16: 12321.55 | V16: 12177.008 | W16: 12065.656 | X16: 11966.21 | Y16: 11879.646 | Z16: 11810.42 | AA16: 11755.599 | AB16: 11704.455 | AC16: 11667.807 | AD16: 11640.296 | AE16: 11624.686 | AF16: 11623.285 | AG16: 11639.25 | AH16: 11669.203 | AI16: 11714.549 | AJ16: 11771.21 | AK16: 11838.642 | AL16: -0.008
B17: E85 | C17: Transportation Energy Use: Light-Duty Vehicle: Ethanol: High oil and gas supply | D17: 46-AEO2020.4.highogs-d112619a | E17: trillion Btu | F17: 17.035625 | G17: 21.426731 | H17: 21.436373 | I17: 22.207422 | J17: 23.357349 | K17: 23.953354 | L17: 26.829184 | M17: 27.316523 | N17: 25.384455 | O17: 24.480259 | P17: 24.010527 | Q17: 27.252335 | R17: 25.556938 | S17: 24.658401 | T17: 23.970201 | U17: 22.945911 | V17: 22.393032 | W17: 22.164173 | X17: 21.680609 | Y17: 21.23234 | Z17: 18.944868 | AA17: 17.040964 | AB17: 16.113234 | AC17: 14.075607 | AD17: 13.99791 | AE17: 13.793528 | AF17: 11.035002 | AG17: 9.906834 | AH17: 8.313334 | AI17: 8.051833 | AJ17: 7.830171 | AK17: 8.098272 | AL17: -0.024
B18: Distillate Fuel Oil (diesel) | C18: Transportation Energy Use: Light-Duty Vehicle: Distillate Fuel Oil: High oil and gas supply | D18: 46-AEO2020.5.highogs-d112619a | E18: trillion Btu | F18: 63.969234 | G18: 66.730286 | H18: 70.605339 | I18: 75.36026 | J18: 79.035683 | K18: 81.421143 | L18: 83.099983 | M18: 84.855759 | N18: 86.411316 | O18: 87.736122 | P18: 88.876724 | Q18: 90.110703 | R18: 91.861847 | S18: 93.189301 | T18: 94.418015 | U18: 95.519661 | V18: 96.34549 | W18: 97.257484 | X18: 98.127975 | Y18: 98.988495 | Z18: 99.829384 | AA18: 101.29481 | AB18: 101.90889 | AC18: 102.41099 | AD18: 103.26958 | AE18: 103.63173 | AF18: 104.11983 | AG18: 104.72976 | AH18: 105.52435 | AI18: 106.4286 | AJ18: 107.42856 | AK18: 108.44432 | AL18: 0.017
B19: Compressed/Liquefied Natural Gas | C19: Transportation Energy Use: Light-Duty Vehicle: Natural Gas: High oil and gas supply | D19: 46-AEO2020.6.highogs-d112619a | E19: trillion Btu | F19: 5.73929 | G19: 5.261131 | H19: 4.957932 | I19: 4.670878 | J19: 4.392184 | K19: 4.119547 | L19: 3.802957 | M19: 3.548156 | N19: 3.399066 | O19: 3.233215 | P19: 3.145408 | Q19: 3.013467 | R19: 2.894538 | S19: 2.803918 | T19: 2.725028 | U19: 2.674252 | V19: 2.632086 | W19: 2.603294 | X19: 2.582047 | Y19: 2.582973 | Z19: 2.570287 | AA19: 2.559894 | AB19: 2.561738 | AC19: 2.564096 | AD19: 2.571058 | AE19: 2.579886 | AF19: 2.591878 | AG19: 2.60693 | AH19: 2.624655 | AI19: 2.646219 | AJ19: 2.668769 | AK19: 2.692575 | AL19: -0.024
B20: Propane | C20: Transportation Energy Use: Light-Duty Vehicle: Propane: High oil and gas supply | D20: 46-AEO2020.7.highogs-d112619a | E20: trillion Btu | F20: 3.780961 | G20: 3.515011 | H20: 3.204999 | I20: 2.921944 | J20: 2.640429 | K20: 2.397087 | L20: 2.190106 | M20: 1.98849 | N20: 1.858488 | O20: 1.748247 | P20: 1.664872 | Q20: 1.616745 | R20: 1.528985 | S20: 1.477662 | T20: 1.43833 | U20: 1.415262 | V20: 1.385289 | W20: 1.372331 | X20: 1.367014 | Y20: 1.36366 | Z20: 1.36307 | AA20: 1.363592 | AB20: 1.377485 | AC20: 1.393089 | AD20: 1.405051 | AE20: 1.420997 | AF20: 1.447421 | AG20: 1.468693 | AH20: 1.499175 | AI20: 1.526954 | AJ20: 1.562022 | AK20: 1.589708 | AL20: -0.028
B21: Electricity | C21: Transportation Energy Use: Light-Duty Vehicle: Electricity: High oil and gas supply | D21: 46-AEO2020.8.highogs-d112619a | E21: trillion Btu | F21: 22.194469 | G21: 29.087179 | H21: 37.69017 | I21: 46.062927 | J21: 54.126274 | K21: 61.878109 | L21: 69.989319 | M21: 78.39698 | N21: 86.801628 | O21: 95.343201 | P21: 104.19643 | Q21: 113.71558 | R21: 124.10317 | S21: 134.95456 | T21: 146.38309 | U21: 158.19431 | V21: 170.38174 | W21: 183.40375 | X21: 196.8738 | Y21: 210.77278 | Z21: 225.06065 | AA21: 239.61594 | AB21: 254.06908 | AC21: 268.569 | AD21: 283.08017 | AE21: 297.4516 | AF21: 311.72357 | AG21: 326.57141 | AH21: 341.17658 | AI21: 356.05942 | AJ21: 371.08896 | AK21: 386.20929 | AL21: 0.097
B22: Hydrogen | C22: Transportation Energy Use: Light-Duty Vehicle: Hydrogen: High oil and gas supply | D22: 46-AEO2020.9.highogs-d112619a | E22: trillion Btu | F22: 0.244584 | G22: 0.270362 | H22: 0.28015 | I22: 0.284073 | J22: 0.28523 | K22: 0.285227 | L22: 0.286521 | M22: 0.291278 | N22: 0.29852 | O22: 0.308114 | P22: 0.320115 | Q22: 0.334829 | R22: 0.351576 | S22: 0.369324 | T22: 0.388562 | U22: 0.409105 | V22: 0.432351 | W22: 0.459401 | X22: 0.489928 | Y22: 0.523536 | Z22: 0.56031 | AA22: 0.599215 | AB22: 0.648974 | AC22: 0.696295 | AD22: 0.746228 | AE22: 0.792258 | AF22: 0.837969 | AG22: 0.884676 | AH22: 0.932552 | AI22: 0.982053 | AJ22: 1.032795 | AK22: 1.084782 | AL22: 0.049
B23: Commercial Light Trucks | C23: Transportation Energy Use: Commercial Light Trucks: Total: High oil and gas supply | D23: 46-AEO2020.29.highogs-d112619a | E23: trillion Btu | F23: 890.89917 | G23: 891.76575 | H23: 895.74506 | I23: 897.72205 | J23: 896.93951 | K23: 893.02771 | L23: 892.48267 | M23: 891.86066 | N23: 892.44971 | O23: 893.48975 | P23: 895.32581 | Q23: 896.54938 | R23: 901.15045 | S23: 904.67493 | T23: 909.68127 | U23: 914.78699 | V23: 920.06 | W23: 926.88635 | X23: 934.08356 | Y23: 941.37378 | Z23: 949.04761 | AA23: 957.56714 | AB23: 966.61407 | AC23: 975.66669 | AD23: 985.86127 | AE23: 997.53308 | AF23: 1010.4193 | AG23: 1026.7943 | AH23: 1039.973 | AI23: 1054.2693 | AJ23: 1068.9308 | AK23: 1083.4713 | AL23: 0.006
B24: Motor Gasoline excluding E85 | C24: Transportation Energy Use: Commercial Light Trucks: Motor Gasoline: High oil and gas supply | D24: 46-AEO2020.30.highogs-d112619a | E24: trillion Btu | F24: 595.89923 | G24: 590.37848 | H24: 588.03449 | I24: 584.95227 | J24: 580.21753 | K24: 574.47736 | L24: 571.12573 | M24: 568.71521 | N24: 568.39905 | O24: 568.5614 | P24: 569.49805 | Q24: 569.23401 | R24: 572.94452 | S24: 575.81103 | T24: 579.96906 | U24: 584.47821 | V24: 589.08411 | W24: 594.81274 | X24: 601.27228 | Y24: 608.02661 | Z24: 615.97882 | AA24: 624.44788 | AB24: 632.54114 | AC24: 641.46631 | AD24: 649.3819 | AE24: 658.06604 | AF24: 669.42169 | AG24: 681.92133 | AH24: 693.21137 | AI24: 704.52264 | AJ24: 716.33118 | AK24: 728.07343 | AL24: 0.006
B25: E85 | C25: Transportation Energy Use: Commercial Light Trucks: E85: High oil and gas supply | D25: 46-AEO2020.31.highogs-d112619a | E25: trillion Btu | F25: 2.821502 | G25: 3.811841 | H25: 4.092943 | I25: 4.468173 | J25: 4.972974 | K25: 5.370958 | L25: 6.37013 | M25: 6.83887 | N25: 6.712829 | O25: 6.851489 | P25: 7.127867 | Q25: 8.574407 | R25: 8.555639 | S25: 8.777064 | T25: 9.085947 | U25: 9.258004 | V25: 9.615754 | W25: 10.112835 | X25: 10.487921 | Y25: 10.873137 | Z25: 10.24772 | AA25: 9.720957 | AB25: 9.683296 | AC25: 8.897798 | AD25: 9.292772 | AE25: 9.608315 | AF25: 8.062674 | AG25: 7.594388 | AH25: 6.6626 | AI25: 6.742769 | AJ25: 6.842918 | AK25: 7.372523 | AL25: 0.031
B26: Distillate Fuel Oil (diesel) | C26: Transportation Energy Use: Commercial Light Trucks: Distillate Fuel Oil: High oil and gas supply | D26: 46-AEO2020.32.highogs-d112619a | E26: trillion Btu | F26: 290.96457 | G26: 296.35336 | H26: 302.31195 | I26: 306.91986 | J26: 310.25812 | K26: 311.58682 | L26: 313.32199 | M26: 314.57257 | N26: 315.55011 | O26: 316.23627 | P26: 316.80414 | Q26: 316.79217 | R26: 317.64154 | S26: 318.01819 | T26: 318.48956 | U26: 318.84314 | V26: 319.07819 | W26: 319.59921 | X26: 319.88031 | Y26: 319.94638 | Z26: 320.20547 | AA26: 320.68985 | AB26: 321.58499 | AC26: 322.39767 | AD26: 324.17795 | AE26: 326.7385 | AF26: 329.69339 | AG26: 333.90292 | AH26: 336.59091 | AI26: 339.34921 | AJ26: 341.94281 | AK26: 344.04034 | AL26: 0.005
... B28: Compressed/Liquefied Natural Gas | C28: Transportation Energy Use: Commercial Light Trucks: Natural Gas: High oil and gas supply | D28: 46-AEO2020.34.highogs-d112619a | E28: trillion Btu | F28: 1.032728 | G28: 0.892461 | H28: 0.834829 | I28: 0.77312 | J28: 0.755125 | K28: 0.736579 | L28: 0.714388 | M28: 0.692867 | N28: 0.672466 | O28: 0.652118 | P28: 0.633047 | Q28: 0.614338 | R28: 0.598108 | S28: 0.584005 | T28: 0.575195 | U28: 0.568726 | V28: 0.564531 | W28: 0.561669 | X28: 0.559763 | Y28: 0.558316 | Z28: 0.557915 | AA28: 0.558718 | AB28: 0.560485 | AC28: 0.563213 | AD28: 0.567338 | AE28: 0.573771 | AF28: 0.582667 | AG28: 0.594227 | AH28: 0.603862 | AI28: 0.618238 | AJ28: 0.637756 | AK28: 0.663077 | AL28: -0.014
B29: Electricity | C29: Transportation Energy Use: Commercial Light Trucks: Electricity: High oil and gas supply | D29: 46-AEO2020.35.highogs-d112619a | E29: trillion Btu | F29: 0 | G29: 0.062943 | H29: 0.122493 | I29: 0.179998 | J29: 0.233812 | K29: 0.284879 | L29: 0.333762 | M29: 0.381328 | N29: 0.413251 | O29: 0.444819 | P29: 0.476749 | Q29: 0.507622 | R29: 0.539985 | S29: 0.571189 | T29: 0.603402 | U29: 0.635684 | V29: 0.668439 | W29: 0.702819 | X29: 0.737713 | Y29: 0.773452 | Z29: 0.809864 | AA29: 0.847996 | AB29: 0.887194 | AC29: 0.927665 | AD29: 0.969063 | AE29: 1.012511 | AF29: 1.058829 | AG29: 1.109148 | AH29: 1.159517 | AI29: 1.213544 | AJ29: 1.270671 | AK29: 1.330036 | AL29: - -
B30: Hydrogen | C30: Transportation Energy Use: Commercial Light Trucks: Hydrogen: High oil and gas supply | D30: 46-AEO2020.36.highogs-d112619a | E30: trillion Btu | F30: 0 | G30: 0 | H30: 0 | I30: 0 | J30: 0 | K30: 0 | L30: 0 | M30: 0 | N30: 0 | O30: 0 | P30: 0 | Q30: 0 | R30: 0 | S30: 0 | T30: 0 | U30: 0 | V30: 0 | W30: 0 | X30: 0 | Y30: 0 | Z30: 0 | AA30: 0 | AB30: 0 | AC30: 0 | AD30: 0 | AE30: 0 | AF30: 0 | AG30: 0 | AH30: 0 | AI30: 0 | AJ30: 0 | AK30: 0 | AL30: - -
B31: Freight Trucks | C31: Transportation Energy Use: Freight Trucks: Total: High oil and gas supply | D31: 46-AEO2020.38.highogs-d112619a | E31: trillion Btu | F31: 5881.6943 | G31: 5905.2188 | H31: 5953.2422 | I31: 5985.7568 | J31: 6012.8101 | K31: 5996.0127 | L31: 5975.9302 | M31: 5946.187 | N31: 5917.5112 | O31: 5879.7192 | P31: 5841.2891 | Q31: 5788.1685 | R31: 5765.2388 | S31: 5732.8813 | T31: 5715.4561 | U31: 5695 | V31: 5689.6113 | W31: 5695.0796 | X31: 5696.8452 | Y31: 5705.6016 | Z31: 5717.1284 | AA31: 5737.4014 | AB31: 5762.4326 | AC31: 5795.2007 | AD31: 5829.8887 | AE31: 5878.4771 | AF31: 5936.4551 | AG31: 6011.3892 | AH31: 6065.646 | AI31: 6135.8477 | AJ31: 6210.5352 | AK31: 6286.1934 | AL31: 0.002
B32: Motor Gasoline | C32: Transportation Energy Use: Freight Trucks: Motor Gasoline: High oil and gas supply | D32: 46-AEO2020.39.highogs-d112619a | E32: trillion Btu | F32: 540.73395 | G32: 537.84741 | H32: 542.10693 | I32: 545.05066 | J32: 549.37195 | K32: 552.02496 | L32: 555.38165 | M32: 559.65637 | N32: 565.34204 | O32: 571.26288 | P32: 577.86774 | Q32: 583.05084 | R32: 591.53278 | S32: 599.66785 | T32: 609.36938 | U32: 618.84637 | V32: 629.91504 | W32: 642.67639 | X32: 654.70227 | Y32: 666.92889 | Z32: 679.97559 | AA32: 693.99664 | AB32: 708.79211 | AC32: 724.6748 | AD32: 740.57458 | AE32: 758.47546 | AF32: 778.18762 | AG32: 799.9342 | AH32: 819.49426 | AI32: 841.4057 | AJ32: 864.521 | AK32: 888.68237 | AL32: 0.016
B33: Distillate Fuel Oil (diesel) | C33: Transportation Energy Use: Freight Trucks: Distillate Fuel Oil: High oil and gas supply | D33: 46-AEO2020.40.highogs-d112619a | E33: trillion Btu | F33: 5283.1289 | G33: 5306.9424 | H33: 5349.1597 | I33: 5377.9526 | J33: 5400.4771 | K33: 5381.6416 | L33: 5358.9424 | M33: 5325.897 | N33: 5292.5874 | O33: 5249.8521 | P33: 5205.5933 | Q33: 5147.7773 | R33: 5116.6934 | S33: 5076.332 | T33: 5048.8105 | U33: 5018.2153 | V33: 5000.5215 | W33: 4991.415 | X33: 4978.9336 | Y33: 4972.6812 | Z33: 4968.2041 | AA33: 4970.9541 | AB33: 4976.9712 | AC33: 4989.2261 | AD33: 5002.5151 | AE33: 5026.9771 | AF33: 5058.8213 | AG33: 5104.1782 | AH33: 5130.8525 | AI33: 5169.6533 | AJ33: 5210.7144 | AK33: 5250.5322 | AL33: 0
B34: Compressed/Liquefied Natural Gas | C34: Transportation Energy Use: Freight Trucks: Natural Gas: High oil and gas supply | D34: 46-AEO2020.41.highogs-d112619a | E34: trillion Btu | F34: 55.134178 | G34: 57.093094 | H34: 58.223106 | I34: 58.559811 | J34: 58.292088 | K34: 57.231102 | L34: 55.931793 | M34: 54.498985 | N34: 53.148956 | O34: 51.826164 | P34: 50.658936 | Q34: 49.543758 | R34: 48.892788 | S34: 48.404388 | T34: 48.36216 | U34: 48.631775 | V34: 49.407616 | W34: 50.719105 | X34: 52.486225 | Y34: 54.779701 | Z34: 57.534088 | AA34: 60.793663 | AB34: 64.598251 | AC34: 68.99585 | AD34: 73.883759 | AE34: 79.473824 | AF34: 85.826004 | AG34: 93.153931 | AH34: 100.89922 | AI34: 109.68303 | AJ34: 119.4538 | AK34: 130.20404 | AL34: 0.028
B35: Propane | C35: Transportation Energy Use: Freight Trucks: Propane: High oil and gas supply | D35: 46-AEO2020.42.highogs-d112619a | E35: trillion Btu | F35: 1.960367 | G35: 2.1215 | H35: 2.266892 | I35: 2.395148 | J35: 2.505968 | K35: 2.583966 | L35: 2.648583 | M35: 2.702281 | N35: 2.752202 | O35: 2.795959 | P35: 2.834885 | Q35: 2.865149 | R35: 2.909102 | S35: 2.949782 | T35: 3.00678 | U35: 3.070877 | V35: 3.144099 | W35: 3.229989 | X35: 3.322527 | Y35: 3.427361 | Z35: 3.540749 | AA35: 3.665833 | AB35: 3.801986 | AC35: 3.948754 | AD35: 4.102226 | AE35: 4.272044 | AF35: 4.457664 | AG35: 4.667796 | AH35: 4.873384 | AI35: 5.103682 | AJ35: 5.342509 | AK35: 5.597682 | AL35: 0.034
B36: E85 | C36: Transportation Energy Use: Freight Trucks: E85: High oil and gas supply | D36: 46-AEO2020.43.highogs-d112619a | E36: trillion Btu | F36: 0.700699 | G36: 0.925426 | H36: 0.974728 | I36: 1.053808 | J36: 1.185472 | K36: 1.333321 | L36: 1.612093 | M36: 1.805291 | N36: 1.836704 | O36: 1.923446 | P36: 2.057781 | Q36: 2.445045 | R36: 2.502855 | S36: 2.601396 | T36: 2.756835 | U36: 2.863327 | V36: 3.019962 | W36: 3.194428 | X36: 3.311527 | Y36: 3.439568 | Z36: 3.27103 | AA36: 3.116567 | AB36: 3.110485 | AC36: 2.896846 | AD36: 3.046129 | AE36: 3.180807 | AF36: 2.711284 | AG36: 2.614661 | AH36: 2.304864 | AI36: 2.363302 | AJ36: 2.421665 | AK36: 2.627188 | AL36: 0.044
B37: Electricity | C37: Transportation Energy Use: Freight Trucks: Electricity: High oil and gas supply | D37: 46-AEO2020.44.highogs-d112619a | E37: trillion Btu | F37: 0.011563 | G37: 0.111948 | H37: 0.198932 | I37: 0.289752 | J37: 0.379985 | K37: 0.465577 | L37: 0.549008 | M37: 0.630298 | N37: 0.711034 | O37: 0.790491 | P37: 0.869031 | Q37: 0.94371 | R37: 1.022145 | S37: 1.098413 | T37: 1.177207 | U37: 1.255466 | V37: 1.337856 | W37: 1.42449 | X37: 1.512214 | Y37: 1.604873 | Z37: 1.698438 | AA37: 1.796811 | AB37: 1.899993 | AC37: 2.008631 | AD37: 2.118988 | AE37: 2.236684 | AF37: 2.361648 | AG37: 2.498656 | AH37: 2.632588 | AI37: 2.779589 | AJ37: 2.935927 | AK37: 3.101992 | AL37: 0.198
B38: Hydrogen | C38: Transportation Energy Use: Freight Trucks: Hydrogen: High oil and gas supply | D38: 46-AEO2020.45.highogs-d112619a | E38: trillion Btu | F38: 0.024469 | G38: 0.176735 | H38: 0.311558 | I38: 0.455412 | J38: 0.597673 | K38: 0.732324 | L38: 0.864866 | M38: 0.997107 | N38: 1.132654 | O38: 1.268626 | P38: 1.407123 | Q38: 1.5425 | R38: 1.686081 | S38: 1.827401 | T38: 1.973075 | U38: 2.116877 | V38: 2.265429 | W38: 2.420031 | X38: 2.576428 | Y38: 2.740173 | Z38: 2.904387 | AA38: 3.077651 | AB38: 3.258968 | AC38: 3.449954 | AD38: 3.64774 | AE38: 3.861133 | AF38: 4.08988 | AG38: 4.34175 | AH38: 4.589088 | AI38: 4.859178 | AJ38: 5.146183 | AK38: 5.447536 | AL38: 0.19
